<?xml version="1.0" ?>
<!-- =================================================================================== -->
<!-- |    This document was autogenerated by xacro from kit_head_on_torso.urdf.xacro   | -->
<!-- |    EDITING THIS FILE BY HAND IS NOT RECOMMENDED                                 | -->
<!-- =================================================================================== -->
<robot name="Eddie" xmlns:xacro="http://www.ros.org/wiki/xacro">
  <material name="KIT/White">
    <color rgba="1 1 1 1.0"/>
  </material>
  <material name="KIT/DarkGrey">
    <color rgba="0.3 0.3 0.3 1.0"/>
  </material>
  <material name="KIT/LightGrey">
    <color rgba="0.8 0.8 0.8 1.0"/>
  </material>
  <material name="KIT/Red">
    <color rgba="0.3 0.3 0.3 1.0"/>
  </material>
  <material name="KIT/Black">
    <color rgba="0 0 0 1.0"/>
  </material>
  <material name="KIT/Orange">
    <color rgba="1.0 0.487 0 1.0"/>
  </material>
  <material name="KIT/Silver">
    <color rgba="1.0 1.0 1.0 1.0"/>
  </material>
  <material name="KIT/Grey">
    <color rgba="0.7 0.7 0.7 1.0"/>
  </material>
  <material name="KIT/Blue">
    <color rgba="0.0 0.0 0.8 1.0"/>
  </material>
  <material name="KIT/HandGray">
    <color rgba="0.953 0.996 0.694 1.0"/>
  </material>
  <material name="KIT/SickBlue">
    <color rgba="0.3058 0.5921 0.7294 1.0"/>
  </material>
  <link name="world_link"/>
  <joint name="world_torso_base_joint" type="fixed">
    <origin xyz="-0.4723 0.6767 -0.734"/>
    <parent link="world_link"/>
    <child link="torso_link"/>
  </joint>
  <link name="torso_link">
    <visual>
      <geometry>
        <mesh filename="package://torso_uibk/meshes/torso.stl"/>
      </geometry>
      <material name="Silver"/>
    </visual>
    <collision>
      <geometry>
        <mesh filename="package://torso_uibk/meshes/torso.stl"/>
      </geometry>
    </collision>
  </link>
  <joint name="world_head_base_joint" type="fixed">
    <origin xyz="-0.4723 0.6767 1.0"/>
    <parent link="world_link"/>
    <child link="calib_head_base_link"/>
  </joint>
  <link name="calib_head_base_link"/>
  <joint name="head_neck_pitch_joint" type="revolute">
    <origin rpy="-1.57079632679 0 0" xyz="0 0 0"/>
    <axis xyz="0 0 1"/>
    <limit effort="204" lower="-0.575958653158" upper="0.575958653158" velocity="3.14159265359"/>
    <safety_controller k_position="30" k_velocity="30" soft_lower_limit="-0.575958653158" soft_upper_limit="0.575958653158"/>
    <dynamics damping="1.0"/>
    <parent link="calib_head_base_link"/>
    <child link="head_head_1_link"/>
  </joint>
  <link name="head_head_1_link">
    <visual>
      <origin rpy="0 0 0" xyz="0 0 0"/>
      <geometry>
        <cylinder length="0.15" radius="0.03"/>
      </geometry>
      <material name="KIT/DarkGrey"/>
    </visual>
    <collision>
      <origin rpy="0 0 0" xyz="0 0 0"/>
      <geometry>
        <cylinder length="0.15" radius="0.03"/>
      </geometry>
    </collision>
  </link>
  <joint name="head_neck_roll_joint" type="revolute">
    <origin rpy="0 1.57079632679 0" xyz="0 0 0"/>
    <axis xyz="0 0 1"/>
    <limit effort="204" lower="-0.488692190558" upper="0.488692190558" velocity="3.14159265359"/>
    <safety_controller k_position="30" k_velocity="30" soft_lower_limit="-0.488692190558" soft_upper_limit="0.488692190558"/>
    <dynamics damping="1.0"/>
    <parent link="head_head_1_link"/>
    <child link="head_head_2_link"/>
  </joint>
  <link name="head_head_2_link">
    <visual>
      <origin rpy="0 0 0" xyz="0 0 0"/>
      <geometry>
        <cylinder length="0.15" radius="0.03"/>
      </geometry>
      <material name="KIT/DarkGrey"/>
    </visual>
    <collision>
      <origin rpy="0 0 0" xyz="0 0 0"/>
      <geometry>
        <cylinder length="0.15" radius="0.03"/>
      </geometry>
    </collision>
  </link>
  <joint name="head_neck_yaw_joint" type="revolute">
    <origin rpy="-1.57079632679 -1.57079632679 0" xyz="0 0 0"/>
    <axis xyz="0 0 1"/>
    <limit effort="204" lower="-1.98967534727" upper="1.98967534727" velocity="3.14159265359"/>
    <safety_controller k_position="30" k_velocity="30" soft_lower_limit="-1.98967534727" soft_upper_limit="1.98967534727"/>
    <dynamics damping="1.0"/>
    <parent link="head_head_2_link"/>
    <child link="head_head_3_link"/>
  </joint>
  <link name="head_head_3_link">
    <visual>
      <origin rpy="0 0 0" xyz="0 0 0"/>
      <geometry>
        <cylinder length="0.15" radius="0.03"/>
      </geometry>
      <material name="KIT/DarkGrey"/>
    </visual>
    <collision>
      <origin rpy="0 0 0" xyz="0 0 0"/>
      <geometry>
        <cylinder length="0.15" radius="0.03"/>
      </geometry>
    </collision>
  </link>
  <joint name="head_head_tilt_joint" type="revolute">
    <origin rpy="1.57079632679 0 0" xyz="0 0 -0.1745"/>
    <axis xyz="0 0 1"/>
    <limit effort="204" lower="-0.698131700798" upper="0.698131700798" velocity="3.14159265359"/>
    <safety_controller k_position="30" k_velocity="30" soft_lower_limit="-0.698131700798" soft_upper_limit="0.698131700798"/>
    <dynamics damping="1.0"/>
    <parent link="head_head_3_link"/>
    <child link="head_head_4_link"/>
  </joint>
  <link name="head_head_4_link">
    <visual>
      <origin rpy="0 0 0" xyz="0 0 0"/>
      <geometry>
        <cylinder length="0.15" radius="0.03"/>
      </geometry>
      <material name="KIT/DarkGrey"/>
    </visual>
    <collision>
      <origin rpy="0 0 0" xyz="0 0 0"/>
      <geometry>
        <cylinder length="0.15" radius="0.03"/>
      </geometry>
    </collision>
  </link>
  <joint name="head_eyes_tilt_joint" type="revolute">
    <origin rpy="0 0 0" xyz="0.1 0 0"/>
    <axis xyz="0 0 1"/>
    <limit effort="204" lower="-0.349065850399" upper="0.349065850399" velocity="3.14159265359"/>
    <safety_controller k_position="30" k_velocity="30" soft_lower_limit="-0.349065850399" soft_upper_limit="0.349065850399"/>
    <dynamics damping="1.0"/>
    <parent link="head_head_4_link"/>
    <child link="head_head_5_link"/>
  </joint>
  <link name="head_head_5_link">
    <visual>
      <origin rpy="0 0 0" xyz="0 0 0"/>
      <geometry>
        <cylinder length="0.03" radius="0.03"/>
      </geometry>
      <material name="KIT/DarkGrey"/>
    </visual>
    <collision>
      <origin rpy="1.57079632679 0 0" xyz="0 0.18 0"/>
      <geometry>
        <cylinder length="0.4" radius="0.15"/>
      </geometry>
    </collision>
  </link>
  <joint name="head_left_eye_joint" type="revolute">
    <origin rpy="1.57079632679 0 0" xyz="0 0 0.0465"/>
    <axis xyz="0 0 1"/>
    <limit effort="204" lower="-0.349065850399" upper="0.349065850399" velocity="3.14159265359"/>
    <safety_controller k_position="30" k_velocity="30" soft_lower_limit="-0.349065850399" soft_upper_limit="0.349065850399"/>
    <dynamics damping="1.0"/>
    <parent link="head_head_5_link"/>
    <child link="head_left_eye_link"/>
  </joint>
  <link name="head_left_eye_link">
    <visual>
      <origin rpy="0 1.57079632679 0" xyz="0.02 0 0"/>
      <geometry>
        <cylinder length="0.02" radius="0.03"/>
      </geometry>
      <material name="KIT/White"/>
    </visual>
    <collision>
      <origin rpy="0 0 0" xyz="0.02 0 0"/>
      <geometry>
        <cylinder length="0.02" radius="0.03"/>
      </geometry>
    </collision>
  </link>
  <joint name="head_right_eye_joint" type="revolute">
    <origin rpy="1.57079632679 0 0" xyz="0 0 -0.0465"/>
    <axis xyz="0 0 1"/>
    <limit effort="204" lower="-0.349065850399" upper="0.349065850399" velocity="3.14159265359"/>
    <safety_controller k_position="30" k_velocity="30" soft_lower_limit="-0.349065850399" soft_upper_limit="0.349065850399"/>
    <dynamics damping="1.0"/>
    <parent link="head_head_5_link"/>
    <child link="head_right_eye_link"/>
  </joint>
  <link name="head_right_eye_link">
    <visual>
      <origin rpy="0 1.57079632679 0" xyz="0.02 0 0"/>
      <geometry>
        <cylinder length="0.02" radius="0.03"/>
      </geometry>
      <material name="KIT/White"/>
    </visual>
    <collision>
      <origin rpy="0 0 0" xyz="0.02 0 0"/>
      <geometry>
        <cylinder length="0.02" radius="0.03"/>
      </geometry>
    </collision>
  </link>
</robot>
